---
title: Como lidar com uma exceção usando try-catch - C# Programming Guide
ms.date: 07/20/2015
helpviewer_keywords:
- exception handling [C#], try/catch blocks
- exceptions [C#], try/catch blocks
- try/catch blocks [C#]
ms.assetid: ca8e3773-980e-4767-8633-7408540e9818
ms.openlocfilehash: adfc53cbe4fd603ac3a6de6b9a0162320d5a2e19
ms.sourcegitcommit: 7588136e355e10cbc2582f389c90c127363c02a5
ms.translationtype: MT
ms.contentlocale: pt-BR
ms.lasthandoff: 03/14/2020
ms.locfileid: "75712280"
---
# <a name="how-to-handle-an-exception-using-trycatch-c-programming-guide"></a><span data-ttu-id="c6443-102">Como lidar com uma exceção usando try/catch (Guia de Programação C#)</span><span class="sxs-lookup"><span data-stu-id="c6443-102">How to handle an exception using try/catch (C# Programming Guide)</span></span>
<span data-ttu-id="c6443-103">A finalidade de um bloco [try-catch](../../language-reference/keywords/try-catch.md) é capturar e manipular uma exceção gerada pelo código de trabalho.</span><span class="sxs-lookup"><span data-stu-id="c6443-103">The purpose of a [try-catch](../../language-reference/keywords/try-catch.md) block is to catch and handle an exception generated by working code.</span></span> <span data-ttu-id="c6443-104">Algumas exceções podem ser manipuladas em um bloco `catch` e o problema pode ser resolvido sem que a exceção seja gerada novamente. No entanto, com mais frequência, a única coisa que você pode fazer é certificar-se de que a exceção apropriada seja gerada.</span><span class="sxs-lookup"><span data-stu-id="c6443-104">Some exceptions can be handled in a `catch` block and the problem solved without the exception being re-thrown; however, more often the only thing that you can do is make sure that the appropriate exception is thrown.</span></span>  
  
## <a name="example"></a><span data-ttu-id="c6443-105">Exemplo</span><span class="sxs-lookup"><span data-stu-id="c6443-105">Example</span></span>  
 <span data-ttu-id="c6443-106">Neste exemplo, <xref:System.IndexOutOfRangeException> não é a exceção mais apropriada: <xref:System.ArgumentOutOfRangeException> faz mais sentido para o método porque o erro é causado pelo argumento `index` passado pelo chamador.</span><span class="sxs-lookup"><span data-stu-id="c6443-106">In this example, <xref:System.IndexOutOfRangeException> is not the most appropriate exception: <xref:System.ArgumentOutOfRangeException> makes more sense for the method because the error is caused by the `index` argument passed in by the caller.</span></span>  
  
 [!code-csharp[csProgGuideExceptions#5](~/samples/snippets/csharp/VS_Snippets_VBCSharp/csProgGuideExceptions/CS/Exceptions.cs#5)]  
  
## <a name="comments"></a><span data-ttu-id="c6443-107">Comentários</span><span class="sxs-lookup"><span data-stu-id="c6443-107">Comments</span></span>  
 <span data-ttu-id="c6443-108">O código que causa uma exceção fica dentro do bloco `try`.</span><span class="sxs-lookup"><span data-stu-id="c6443-108">The code that causes an exception is enclosed in the `try` block.</span></span> <span data-ttu-id="c6443-109">A instrução `catch` é adicionada logo após para manipular `IndexOutOfRangeException`, se ocorrer.</span><span class="sxs-lookup"><span data-stu-id="c6443-109">A `catch` statement is added immediately after to handle `IndexOutOfRangeException`, if it occurs.</span></span> <span data-ttu-id="c6443-110">O bloco `catch` manipula o `IndexOutOfRangeException` e gera a exceção `ArgumentOutOfRangeException`, que é mais adequada.</span><span class="sxs-lookup"><span data-stu-id="c6443-110">The `catch` block handles the `IndexOutOfRangeException` and throws the more appropriate `ArgumentOutOfRangeException` exception instead.</span></span> <span data-ttu-id="c6443-111">Para fornecer ao chamador tantas informações quanto possível, considere especificar a exceção original como o <xref:System.Exception.InnerException%2A> da nova exceção.</span><span class="sxs-lookup"><span data-stu-id="c6443-111">In order to provide the caller with as much information as possible, consider specifying the original exception as the <xref:System.Exception.InnerException%2A> of the new exception.</span></span> <span data-ttu-id="c6443-112">Uma vez que a propriedade <xref:System.Exception.InnerException%2A> é [readonly](../../language-reference/keywords/readonly.md), você precisa atribuí-la no construtor da nova exceção.</span><span class="sxs-lookup"><span data-stu-id="c6443-112">Because the <xref:System.Exception.InnerException%2A> property is [readonly](../../language-reference/keywords/readonly.md), you must assign it in the constructor of the new exception.</span></span>  
  
## <a name="see-also"></a><span data-ttu-id="c6443-113">Confira também</span><span class="sxs-lookup"><span data-stu-id="c6443-113">See also</span></span>

- [<span data-ttu-id="c6443-114">C# Guia de Programação</span><span class="sxs-lookup"><span data-stu-id="c6443-114">C# Programming Guide</span></span>](../index.md)
- [<span data-ttu-id="c6443-115">Exceções e tratamento de exceções</span><span class="sxs-lookup"><span data-stu-id="c6443-115">Exceptions and Exception Handling</span></span>](./index.md)
- [<span data-ttu-id="c6443-116">Tratamento de exceção</span><span class="sxs-lookup"><span data-stu-id="c6443-116">Exception Handling</span></span>](./exception-handling.md)
